2017-12-15 21:48:56,427 [Thread-22:17504] [django.request:135] [exception:handle_uncaught_exception] [ERROR]- Internal Server Error: /mainsite/
Traceback (most recent call last):
  File "C:\Python27\lib\site-packages\django\core\handlers\exception.py", line 41, in inner
    response = get_response(request)
  File "C:\Python27\lib\site-packages\django\core\handlers\base.py", line 187, in _get_response
    response = self.process_exception_by_middleware(e, request)
  File "C:\Python27\lib\site-packages\django\core\handlers\base.py", line 185, in _get_response
    response = wrapped_callback(request, *callback_args, **callback_kwargs)
  File "D:\workspace\my_django_blog-master\mainsite\views.py", line 19, in homepage
    template = get_template('mainsite/index.html')
  File "C:\Python27\lib\site-packages\django\template\loader.py", line 25, in get_template
    raise TemplateDoesNotExist(template_name, chain=chain)
TemplateDoesNotExist: mainsite/index.html
2017-12-18 20:03:51,917 [Thread-2:18900] [django.request:135] [exception:handle_uncaught_exception] [ERROR]- Internal Server Error: /mainsite/lottery
Traceback (most recent call last):
  File "C:\Python27\lib\site-packages\django\core\handlers\exception.py", line 41, in inner
    response = get_response(request)
  File "C:\Python27\lib\site-packages\django\core\handlers\base.py", line 187, in _get_response
    response = self.process_exception_by_middleware(e, request)
  File "C:\Python27\lib\site-packages\django\core\handlers\base.py", line 185, in _get_response
    response = wrapped_callback(request, *callback_args, **callback_kwargs)
  File "D:\workspace\my_django_blog-master\mainsite\views.py", line 64, in lottery
    c = [random.radnint(a, b) for _ in range(3)]
AttributeError: 'module' object has no attribute 'radnint'
2017-12-18 20:06:12,961 [Thread-4:19392] [django.request:135] [exception:handle_uncaught_exception] [ERROR]- Internal Server Error: /mainsite/lottery
Traceback (most recent call last):
  File "C:\Python27\lib\site-packages\django\core\handlers\exception.py", line 41, in inner
    response = get_response(request)
  File "C:\Python27\lib\site-packages\django\core\handlers\base.py", line 187, in _get_response
    response = self.process_exception_by_middleware(e, request)
  File "C:\Python27\lib\site-packages\django\core\handlers\base.py", line 185, in _get_response
    response = wrapped_callback(request, *callback_args, **callback_kwargs)
  File "D:\workspace\my_django_blog-master\mainsite\views.py", line 65, in lottery
    return render_to_response('mainsite/lottery.html',{"c":c})
  File "C:\Python27\lib\site-packages\django\shortcuts.py", line 21, in render_to_response
    content = loader.render_to_string(template_name, context, using=using)
  File "C:\Python27\lib\site-packages\django\template\loader.py", line 67, in render_to_string
    template = get_template(template_name, using=using)
  File "C:\Python27\lib\site-packages\django\template\loader.py", line 21, in get_template
    return engine.get_template(template_name)
  File "C:\Python27\lib\site-packages\django\template\backends\django.py", line 39, in get_template
    return Template(self.engine.get_template(template_name), self)
  File "C:\Python27\lib\site-packages\django\template\engine.py", line 162, in get_template
    template, origin = self.find_template(template_name)
  File "C:\Python27\lib\site-packages\django\template\engine.py", line 136, in find_template
    name, template_dirs=dirs, skip=skip,
  File "C:\Python27\lib\site-packages\django\template\loaders\base.py", line 44, in get_template
    contents, origin, origin.template_name, self.engine,
  File "C:\Python27\lib\site-packages\django\template\base.py", line 191, in __init__
    self.nodelist = self.compile_nodelist()
  File "C:\Python27\lib\site-packages\django\template\base.py", line 230, in compile_nodelist
    return parser.parse()
  File "C:\Python27\lib\site-packages\django\template\base.py", line 509, in parse
    self.invalid_block_tag(token, command, parse_until)
  File "C:\Python27\lib\site-packages\django\template\base.py", line 571, in invalid_block_tag
    "or load this tag?" % (token.lineno, command)
TemplateSyntaxError: Invalid block tag on line 14: 'c[0]'. Did you forget to register or load this tag?
2017-12-18 20:16:02,260 [Thread-2:12096] [django.request:135] [exception:handle_uncaught_exception] [ERROR]- Internal Server Error: /mainsite/lottery
Traceback (most recent call last):
  File "C:\Python27\lib\site-packages\django\core\handlers\exception.py", line 41, in inner
    response = get_response(request)
  File "C:\Python27\lib\site-packages\django\core\handlers\base.py", line 187, in _get_response
    response = self.process_exception_by_middleware(e, request)
  File "C:\Python27\lib\site-packages\django\core\handlers\base.py", line 185, in _get_response
    response = wrapped_callback(request, *callback_args, **callback_kwargs)
  File "D:\workspace\my_django_blog-master\mainsite\views.py", line 64, in lottery
    return render_to_response('mainsite/lottery.html',{"c":c})
  File "C:\Python27\lib\site-packages\django\shortcuts.py", line 21, in render_to_response
    content = loader.render_to_string(template_name, context, using=using)
  File "C:\Python27\lib\site-packages\django\template\loader.py", line 67, in render_to_string
    template = get_template(template_name, using=using)
  File "C:\Python27\lib\site-packages\django\template\loader.py", line 21, in get_template
    return engine.get_template(template_name)
  File "C:\Python27\lib\site-packages\django\template\backends\django.py", line 39, in get_template
    return Template(self.engine.get_template(template_name), self)
  File "C:\Python27\lib\site-packages\django\template\engine.py", line 162, in get_template
    template, origin = self.find_template(template_name)
  File "C:\Python27\lib\site-packages\django\template\engine.py", line 136, in find_template
    name, template_dirs=dirs, skip=skip,
  File "C:\Python27\lib\site-packages\django\template\loaders\base.py", line 44, in get_template
    contents, origin, origin.template_name, self.engine,
  File "C:\Python27\lib\site-packages\django\template\base.py", line 191, in __init__
    self.nodelist = self.compile_nodelist()
  File "C:\Python27\lib\site-packages\django\template\base.py", line 230, in compile_nodelist
    return parser.parse()
  File "C:\Python27\lib\site-packages\django\template\base.py", line 486, in parse
    raise self.error(token, e)
TemplateSyntaxError: Could not parse the remainder: '[0]' from 'c[0]'
2017-12-27 20:22:21,874 [Thread-46:22828] [django.request:135] [exception:handle_uncaught_exception] [ERROR]- Internal Server Error: /admin/bookapp/book/add/
Traceback (most recent call last):
  File "C:\Python27\lib\site-packages\django\core\handlers\exception.py", line 41, in inner
    response = get_response(request)
  File "C:\Python27\lib\site-packages\django\core\handlers\base.py", line 187, in _get_response
    response = self.process_exception_by_middleware(e, request)
  File "C:\Python27\lib\site-packages\django\core\handlers\base.py", line 185, in _get_response
    response = wrapped_callback(request, *callback_args, **callback_kwargs)
  File "C:\Python27\lib\site-packages\django\contrib\admin\options.py", line 551, in wrapper
    return self.admin_site.admin_view(view)(*args, **kwargs)
  File "C:\Python27\lib\site-packages\django\utils\decorators.py", line 149, in _wrapped_view
    response = view_func(request, *args, **kwargs)
  File "C:\Python27\lib\site-packages\django\views\decorators\cache.py", line 57, in _wrapped_view_func
    response = view_func(request, *args, **kwargs)
  File "C:\Python27\lib\site-packages\django\contrib\admin\sites.py", line 224, in inner
    return view(request, *args, **kwargs)
  File "C:\Python27\lib\site-packages\django\contrib\admin\options.py", line 1508, in add_view
    return self.changeform_view(request, None, form_url, extra_context)
  File "C:\Python27\lib\site-packages\django\utils\decorators.py", line 67, in _wrapper
    return bound_func(*args, **kwargs)
  File "C:\Python27\lib\site-packages\django\utils\decorators.py", line 149, in _wrapped_view
    response = view_func(request, *args, **kwargs)
  File "C:\Python27\lib\site-packages\django\utils\decorators.py", line 63, in bound_func
    return func.__get__(self, type(self))(*args2, **kwargs2)
  File "C:\Python27\lib\site-packages\django\contrib\admin\options.py", line 1408, in changeform_view
    return self._changeform_view(request, object_id, form_url, extra_context)
  File "C:\Python27\lib\site-packages\django\contrib\admin\options.py", line 1452, in _changeform_view
    self.log_addition(request, new_object, change_message)
  File "C:\Python27\lib\site-packages\django\contrib\admin\options.py", line 724, in log_addition
    object_repr=force_text(object),
  File "C:\Python27\lib\site-packages\django\utils\encoding.py", line 78, in force_text
    s = six.text_type(s)
  File "D:\workspace\my_django_blog-master\bookapp\models.py", line 26, in __unicode__
    return str(self.title)
UnicodeEncodeError: 'ascii' codec can't encode characters in position 0-3: ordinal not in range(128)
2017-12-27 20:24:44,321 [Thread-4:23188] [django.request:135] [exception:handle_uncaught_exception] [ERROR]- Internal Server Error: /admin/bookapp/book/add/
Traceback (most recent call last):
  File "C:\Python27\lib\site-packages\django\core\handlers\exception.py", line 41, in inner
    response = get_response(request)
  File "C:\Python27\lib\site-packages\django\core\handlers\base.py", line 187, in _get_response
    response = self.process_exception_by_middleware(e, request)
  File "C:\Python27\lib\site-packages\django\core\handlers\base.py", line 185, in _get_response
    response = wrapped_callback(request, *callback_args, **callback_kwargs)
  File "C:\Python27\lib\site-packages\django\contrib\admin\options.py", line 551, in wrapper
    return self.admin_site.admin_view(view)(*args, **kwargs)
  File "C:\Python27\lib\site-packages\django\utils\decorators.py", line 149, in _wrapped_view
    response = view_func(request, *args, **kwargs)
  File "C:\Python27\lib\site-packages\django\views\decorators\cache.py", line 57, in _wrapped_view_func
    response = view_func(request, *args, **kwargs)
  File "C:\Python27\lib\site-packages\django\contrib\admin\sites.py", line 224, in inner
    return view(request, *args, **kwargs)
  File "C:\Python27\lib\site-packages\django\contrib\admin\options.py", line 1508, in add_view
    return self.changeform_view(request, None, form_url, extra_context)
  File "C:\Python27\lib\site-packages\django\utils\decorators.py", line 67, in _wrapper
    return bound_func(*args, **kwargs)
  File "C:\Python27\lib\site-packages\django\utils\decorators.py", line 149, in _wrapped_view
    response = view_func(request, *args, **kwargs)
  File "C:\Python27\lib\site-packages\django\utils\decorators.py", line 63, in bound_func
    return func.__get__(self, type(self))(*args2, **kwargs2)
  File "C:\Python27\lib\site-packages\django\contrib\admin\options.py", line 1408, in changeform_view
    return self._changeform_view(request, object_id, form_url, extra_context)
  File "C:\Python27\lib\site-packages\django\contrib\admin\options.py", line 1448, in _changeform_view
    self.save_model(request, new_object, form, not add)
  File "C:\Python27\lib\site-packages\django\contrib\admin\options.py", line 979, in save_model
    obj.save()
  File "C:\Python27\lib\site-packages\django\db\models\base.py", line 808, in save
    force_update=force_update, update_fields=update_fields)
  File "C:\Python27\lib\site-packages\django\db\models\base.py", line 838, in save_base
    updated = self._save_table(raw, cls, force_insert, force_update, using, update_fields)
  File "C:\Python27\lib\site-packages\django\db\models\base.py", line 924, in _save_table
    result = self._do_insert(cls._base_manager, using, fields, update_pk, raw)
  File "C:\Python27\lib\site-packages\django\db\models\base.py", line 963, in _do_insert
    using=using, raw=raw)
  File "C:\Python27\lib\site-packages\django\db\models\manager.py", line 85, in manager_method
    return getattr(self.get_queryset(), name)(*args, **kwargs)
  File "C:\Python27\lib\site-packages\django\db\models\query.py", line 1076, in _insert
    return query.get_compiler(using=using).execute_sql(return_id)
  File "C:\Python27\lib\site-packages\django\db\models\sql\compiler.py", line 1107, in execute_sql
    cursor.execute(sql, params)
  File "C:\Python27\lib\site-packages\django\db\backends\utils.py", line 80, in execute
    return super(CursorDebugWrapper, self).execute(sql, params)
  File "C:\Python27\lib\site-packages\django\db\backends\utils.py", line 65, in execute
    return self.cursor.execute(sql, params)
  File "C:\Python27\lib\site-packages\django\db\utils.py", line 94, in __exit__
    six.reraise(dj_exc_type, dj_exc_value, traceback)
  File "C:\Python27\lib\site-packages\django\db\backends\utils.py", line 65, in execute
    return self.cursor.execute(sql, params)
  File "C:\Python27\lib\site-packages\django\db\backends\sqlite3\base.py", line 328, in execute
    return Database.Cursor.execute(self, query, params)
IntegrityError: NOT NULL constraint failed: bookapp_book.pages
